{
 "cells": [
  {
   "cell_type": "code",
   "execution_count": 1,
   "id": "519b31ff",
   "metadata": {},
   "outputs": [],
   "source": [
    "#loading mnist\n",
    "from keras.datasets import mnist\n",
    "#loading sequential\n",
    "from keras.models import Sequential\n",
    "#loading the functions for analysis\n",
    "from keras.layers import Dense, Dropout, Conv2D, MaxPool2D, Flatten\n",
    "#loading layers from tesor flow\n",
    "from tensorflow.keras import datasets, layers, models\n",
    "#loading utilities\n",
    "from keras.utils import np_utils\n",
    "#loading metrics to know the accuracy of the model\n",
    "from sklearn.metrics import accuracy_score\n"
   ]
  },
  {
   "cell_type": "code",
   "execution_count": 2,
   "id": "956de1f6",
   "metadata": {},
   "outputs": [],
   "source": [
    "import tensorflow as tf#importing tensorflow\n",
    "import os#importing os\n",
    "import numpy as np#importing numpy library\n",
    "import pandas as pd#importing pandas library"
   ]
  },
  {
   "cell_type": "code",
   "execution_count": 3,
   "id": "5d7796c3",
   "metadata": {},
   "outputs": [],
   "source": [
    "#changing the directory path\n",
    "os.chdir('D://DKIT//dissertation//Dataset_of_Tomato_Leaves//plantvillage//Preprocessed_data//64//vector//')\n",
    "#reading numpy array data\n",
    "pixels = np.load('rgb_data.npy')\n",
    "#reading csv file\n",
    "data = pd.read_csv('rgb_data.csv')"
   ]
  },
  {
   "cell_type": "code",
   "execution_count": 4,
   "id": "2485114d",
   "metadata": {},
   "outputs": [],
   "source": [
    "#reading each array and reshaping them and converting to a seperate array\n",
    "features = []\n",
    "for i in pixels:\n",
    "    k = []\n",
    "    k = np.asarray(i,dtype='uint8')\n",
    "    k = np.reshape(k,(64,64,3))\n",
    "    features.append(k)"
   ]
  },
  {
   "cell_type": "code",
   "execution_count": 5,
   "id": "f766f5bc",
   "metadata": {},
   "outputs": [],
   "source": [
    "#taking disease column as the response variable\n",
    "target = data['disease']\n",
    "diseases=target.unique()\n",
    "target.replace(diseases,[1,2,3,4,5,6,7,8,9,10], inplace=True)"
   ]
  },
  {
   "cell_type": "code",
   "execution_count": 6,
   "id": "be79d860",
   "metadata": {},
   "outputs": [],
   "source": [
    "#splitting the data to test and train\n",
    "from sklearn.model_selection import train_test_split\n",
    "xtrain,xtest,ytrain,ytest = train_test_split(features,target, test_size=0.20, random_state=24)"
   ]
  },
  {
   "cell_type": "code",
   "execution_count": 7,
   "id": "f5e45ce5",
   "metadata": {},
   "outputs": [
    {
     "data": {
      "text/plain": [
       "11624"
      ]
     },
     "execution_count": 7,
     "metadata": {},
     "output_type": "execute_result"
    }
   ],
   "source": [
    "len(xtrain)"
   ]
  },
  {
   "cell_type": "code",
   "execution_count": 8,
   "id": "b52b7913",
   "metadata": {},
   "outputs": [
    {
     "data": {
      "text/plain": [
       "11624"
      ]
     },
     "execution_count": 8,
     "metadata": {},
     "output_type": "execute_result"
    }
   ],
   "source": [
    "len(ytrain)"
   ]
  },
  {
   "cell_type": "code",
   "execution_count": 9,
   "id": "e1719b98",
   "metadata": {},
   "outputs": [],
   "source": [
    "ytrain = tf.stack(ytrain)\n",
    "xtrain = tf.stack(xtrain)"
   ]
  },
  {
   "cell_type": "code",
   "execution_count": 10,
   "id": "6b30fe76",
   "metadata": {},
   "outputs": [
    {
     "data": {
      "text/plain": [
       "11624"
      ]
     },
     "execution_count": 10,
     "metadata": {},
     "output_type": "execute_result"
    }
   ],
   "source": [
    "len(xtrain)"
   ]
  },
  {
   "cell_type": "code",
   "execution_count": 11,
   "id": "15c1719a",
   "metadata": {},
   "outputs": [],
   "source": [
    "model = Sequential()\n",
    "# convolutional layer\n",
    "model.add(Conv2D(25, kernel_size=(3,3), strides=(1,1), padding='valid', activation='relu', input_shape=(64,64,3)))\n",
    "model.add(MaxPool2D(pool_size=(1,1)))\n",
    "# flatten output of conv\n",
    "model.add(Flatten())\n",
    "# hidden layer\n",
    "model.add(Dense(100, activation='relu'))\n",
    "# output layer\n",
    "model.add(Dense(10, activation='softmax'))\n",
    "\n",
    "# compiling the sequential model\n",
    "model.compile(loss='categorical_crossentropy', metrics=['accuracy'], optimizer='adam')"
   ]
  },
  {
   "cell_type": "code",
   "execution_count": 12,
   "id": "a0c95a83",
   "metadata": {},
   "outputs": [
    {
     "name": "stdout",
     "output_type": "stream",
     "text": [
      "Epoch 1/10\n"
     ]
    },
    {
     "ename": "ValueError",
     "evalue": "in user code:\n\n    File \"C:\\Users\\ravic\\anaconda3\\lib\\site-packages\\keras\\engine\\training.py\", line 1051, in train_function  *\n        return step_function(self, iterator)\n    File \"C:\\Users\\ravic\\anaconda3\\lib\\site-packages\\keras\\engine\\training.py\", line 1040, in step_function  **\n        outputs = model.distribute_strategy.run(run_step, args=(data,))\n    File \"C:\\Users\\ravic\\anaconda3\\lib\\site-packages\\keras\\engine\\training.py\", line 1030, in run_step  **\n        outputs = model.train_step(data)\n    File \"C:\\Users\\ravic\\anaconda3\\lib\\site-packages\\keras\\engine\\training.py\", line 890, in train_step\n        loss = self.compute_loss(x, y, y_pred, sample_weight)\n    File \"C:\\Users\\ravic\\anaconda3\\lib\\site-packages\\keras\\engine\\training.py\", line 948, in compute_loss\n        return self.compiled_loss(\n    File \"C:\\Users\\ravic\\anaconda3\\lib\\site-packages\\keras\\engine\\compile_utils.py\", line 201, in __call__\n        loss_value = loss_obj(y_t, y_p, sample_weight=sw)\n    File \"C:\\Users\\ravic\\anaconda3\\lib\\site-packages\\keras\\losses.py\", line 139, in __call__\n        losses = call_fn(y_true, y_pred)\n    File \"C:\\Users\\ravic\\anaconda3\\lib\\site-packages\\keras\\losses.py\", line 243, in call  **\n        return ag_fn(y_true, y_pred, **self._fn_kwargs)\n    File \"C:\\Users\\ravic\\anaconda3\\lib\\site-packages\\keras\\losses.py\", line 1787, in categorical_crossentropy\n        return backend.categorical_crossentropy(\n    File \"C:\\Users\\ravic\\anaconda3\\lib\\site-packages\\keras\\backend.py\", line 5119, in categorical_crossentropy\n        target.shape.assert_is_compatible_with(output.shape)\n\n    ValueError: Shapes (None, 1) and (None, 10) are incompatible\n",
     "output_type": "error",
     "traceback": [
      "\u001b[1;31m---------------------------------------------------------------------------\u001b[0m",
      "\u001b[1;31mValueError\u001b[0m                                Traceback (most recent call last)",
      "Input \u001b[1;32mIn [12]\u001b[0m, in \u001b[0;36m<cell line: 2>\u001b[1;34m()\u001b[0m\n\u001b[0;32m      1\u001b[0m \u001b[38;5;66;03m# training the model for 10 epochs\u001b[39;00m\n\u001b[1;32m----> 2\u001b[0m \u001b[43mmodel\u001b[49m\u001b[38;5;241;43m.\u001b[39;49m\u001b[43mfit\u001b[49m\u001b[43m(\u001b[49m\u001b[43mxtrain\u001b[49m\u001b[43m,\u001b[49m\u001b[43m \u001b[49m\u001b[43mytrain\u001b[49m\u001b[43m,\u001b[49m\u001b[43m \u001b[49m\u001b[43mepochs\u001b[49m\u001b[38;5;241;43m=\u001b[39;49m\u001b[38;5;241;43m10\u001b[39;49m\u001b[43m,\u001b[49m\u001b[43m \u001b[49m\u001b[43mvalidation_data\u001b[49m\u001b[38;5;241;43m=\u001b[39;49m\u001b[43m(\u001b[49m\u001b[43mxtest\u001b[49m\u001b[43m,\u001b[49m\u001b[43m \u001b[49m\u001b[43mytest\u001b[49m\u001b[43m)\u001b[49m\u001b[43m)\u001b[49m\n",
      "File \u001b[1;32m~\\anaconda3\\lib\\site-packages\\keras\\utils\\traceback_utils.py:67\u001b[0m, in \u001b[0;36mfilter_traceback.<locals>.error_handler\u001b[1;34m(*args, **kwargs)\u001b[0m\n\u001b[0;32m     65\u001b[0m \u001b[38;5;28;01mexcept\u001b[39;00m \u001b[38;5;167;01mException\u001b[39;00m \u001b[38;5;28;01mas\u001b[39;00m e:  \u001b[38;5;66;03m# pylint: disable=broad-except\u001b[39;00m\n\u001b[0;32m     66\u001b[0m   filtered_tb \u001b[38;5;241m=\u001b[39m _process_traceback_frames(e\u001b[38;5;241m.\u001b[39m__traceback__)\n\u001b[1;32m---> 67\u001b[0m   \u001b[38;5;28;01mraise\u001b[39;00m e\u001b[38;5;241m.\u001b[39mwith_traceback(filtered_tb) \u001b[38;5;28;01mfrom\u001b[39;00m \u001b[38;5;28mNone\u001b[39m\n\u001b[0;32m     68\u001b[0m \u001b[38;5;28;01mfinally\u001b[39;00m:\n\u001b[0;32m     69\u001b[0m   \u001b[38;5;28;01mdel\u001b[39;00m filtered_tb\n",
      "File \u001b[1;32m~\\AppData\\Local\\Temp\\__autograph_generated_filev0yl2xmu.py:15\u001b[0m, in \u001b[0;36mouter_factory.<locals>.inner_factory.<locals>.tf__train_function\u001b[1;34m(iterator)\u001b[0m\n\u001b[0;32m     13\u001b[0m \u001b[38;5;28;01mtry\u001b[39;00m:\n\u001b[0;32m     14\u001b[0m     do_return \u001b[38;5;241m=\u001b[39m \u001b[38;5;28;01mTrue\u001b[39;00m\n\u001b[1;32m---> 15\u001b[0m     retval_ \u001b[38;5;241m=\u001b[39m ag__\u001b[38;5;241m.\u001b[39mconverted_call(ag__\u001b[38;5;241m.\u001b[39mld(step_function), (ag__\u001b[38;5;241m.\u001b[39mld(\u001b[38;5;28mself\u001b[39m), ag__\u001b[38;5;241m.\u001b[39mld(iterator)), \u001b[38;5;28;01mNone\u001b[39;00m, fscope)\n\u001b[0;32m     16\u001b[0m \u001b[38;5;28;01mexcept\u001b[39;00m:\n\u001b[0;32m     17\u001b[0m     do_return \u001b[38;5;241m=\u001b[39m \u001b[38;5;28;01mFalse\u001b[39;00m\n",
      "\u001b[1;31mValueError\u001b[0m: in user code:\n\n    File \"C:\\Users\\ravic\\anaconda3\\lib\\site-packages\\keras\\engine\\training.py\", line 1051, in train_function  *\n        return step_function(self, iterator)\n    File \"C:\\Users\\ravic\\anaconda3\\lib\\site-packages\\keras\\engine\\training.py\", line 1040, in step_function  **\n        outputs = model.distribute_strategy.run(run_step, args=(data,))\n    File \"C:\\Users\\ravic\\anaconda3\\lib\\site-packages\\keras\\engine\\training.py\", line 1030, in run_step  **\n        outputs = model.train_step(data)\n    File \"C:\\Users\\ravic\\anaconda3\\lib\\site-packages\\keras\\engine\\training.py\", line 890, in train_step\n        loss = self.compute_loss(x, y, y_pred, sample_weight)\n    File \"C:\\Users\\ravic\\anaconda3\\lib\\site-packages\\keras\\engine\\training.py\", line 948, in compute_loss\n        return self.compiled_loss(\n    File \"C:\\Users\\ravic\\anaconda3\\lib\\site-packages\\keras\\engine\\compile_utils.py\", line 201, in __call__\n        loss_value = loss_obj(y_t, y_p, sample_weight=sw)\n    File \"C:\\Users\\ravic\\anaconda3\\lib\\site-packages\\keras\\losses.py\", line 139, in __call__\n        losses = call_fn(y_true, y_pred)\n    File \"C:\\Users\\ravic\\anaconda3\\lib\\site-packages\\keras\\losses.py\", line 243, in call  **\n        return ag_fn(y_true, y_pred, **self._fn_kwargs)\n    File \"C:\\Users\\ravic\\anaconda3\\lib\\site-packages\\keras\\losses.py\", line 1787, in categorical_crossentropy\n        return backend.categorical_crossentropy(\n    File \"C:\\Users\\ravic\\anaconda3\\lib\\site-packages\\keras\\backend.py\", line 5119, in categorical_crossentropy\n        target.shape.assert_is_compatible_with(output.shape)\n\n    ValueError: Shapes (None, 1) and (None, 10) are incompatible\n"
     ]
    }
   ],
   "source": [
    "# training the model for 10 epochs\n",
    "model.fit(xtrain, ytrain, epochs=10, validation_data=(xtest, ytest))"
   ]
  }
 ],
 "metadata": {
  "kernelspec": {
   "display_name": "Python 3 (ipykernel)",
   "language": "python",
   "name": "python3"
  },
  "language_info": {
   "codemirror_mode": {
    "name": "ipython",
    "version": 3
   },
   "file_extension": ".py",
   "mimetype": "text/x-python",
   "name": "python",
   "nbconvert_exporter": "python",
   "pygments_lexer": "ipython3",
   "version": "3.9.12"
  }
 },
 "nbformat": 4,
 "nbformat_minor": 5
}
